Workbook

Sheet Resumo
L1: Entradas nas últimas semanas | Q1: Histórico Atendimento | U1: Mensagens Transacionadas
B2: Mês Ref | C2: Qted | D2: Total Emitido (R$) | E2: Total Pago (R$) | F2: Valor em Acordo | G2: Valor Inadimplente | H2: % inadimplência | I2: % inadimplência anterior gestão HUBE | Q2: Ano | R2: Mês | S2: Quantidade | U2: Mês | V2: Entradas | W2: Saídas
B3: 45658 | C3: 84 | D3: 19964.24 | E3: 19059.44 | F3: 0 | G3: 904.8 | H3: 0.045321034 | I3: 0.12 | Q3: 2025 | R3: Agosto | S3: 135 | U3: Agosto | V3: 578 | W3: 662
B4: 45689 | C4: 50 | D4: 16003.59 | E4: 15264.88 | F4: 0 | G4: 738.71 | H4: 0.046159018 | I4: 0.11 | Q4: 2025 | R4: Setembro | S4: 150 | U4: Setembro | V4: 1183 | W4: 1533
B5: 45717 | C5: 55 | D5: 17915 | E5: 17007.83 | F5: 0 | G5: 907.17 | H5: 0.050637455 | I5: 0.3 | Q5: 2025 | R5: Outubro | S5: 78 | U5: Outubro | V5: 671 | W5: 909
B6: 45748 | C6: 86 | D6: 18900.91 | E6: 16189.3 | F6: 175.21 | G6: 2536.4 | H6: 0.1341946 | I6: 0.32
B7: 45778 | C7: 83 | D7: 16645.9 | E7: 14193.639 | F7: 0 | G7: 2452.261 | H7: 0.14731922 | I7: 0.4
B8: 45809 | C8: 63 | D8: 9822.37 | E8: 9532.5733 | F8: 0 | G8: 289.79667 | H8: 0.029503742
B9: 45839 | C9: 75 | D9: 12120.21 | E9: 12060.14 | F9: 161.56 | G9: -101.49 | H9: 0
B10: 45870 | C10: 78 | D10: 14372.97 | E10: 14030.1 | F10: 172.03 | G10: 170.84 | H10: 0.0118862
B11: 45901 | C11: 79 | D11: 18122.97 | E11: 17328.501 | F11: 0 | G11: 794.46947 | H11: 0.043837708
B12: 45931 | C12: 85 | D12: 23671.21 | E12: 22313.22 | F12: 0 | G12: 1357.99 | H12: 0.057368846
B13: 45962 | C13: 87 | D13: 28544.62 | E13: 18614.41 | F13: 0 | G13: 9930.21 | H13: 0.34788377
B14: Total Geral | C14: 825 | D14: 196083.99 | E14: 175594.03 | F14: 508.8 | G14: 8692.9571 | H14: 0.056539886
N42: Etapa | O42: Tempo Semanal | P42: Responsável
N43: Atendimento | O43: 3 horas | P43: Isabella
N44: Faturamento | O44: 0,5 horas | P44: Isabella
N45: Cobrança | O45: 5 horas | P45: Adriano
N46: Report EGS | O46: 1 hora | P46: Carol
N47: Total | O47: 9,5 horas

Sheet base
A2: INSTALAÇÃO | B2: NOME COMPLETO OU RAZÃO SOCIAL | C2: CNPJ | D2: DISTRIBUIDORA | E2: STATUS RATEIO | F2: STATUS DE CLIENTE | G2: MOTIVO RETIRADA | H2: DATA RETIRADA DE RATEIO | I2: E-MAIL | J2: TELEFONE | K2: FORNECIMENTO | L2: DESCONTO CONTRATADO | M2: REGIÃO | N2: CEP | O2: UF | P2: ENDEREÇO COMPLETO | Q2: CONS. DISPONÍVEL KWH | R2: CONSUMO ALVO | S2: BOLETOS ATRASADOS
A3: 10/1017804-4 | B3: IGREJA DO EVANGELHO QUADRANGULAR | C3: 62.955.505/8789-87 | D3: ENERGISA MS | E3: ACOMPANHAR CRÉDITO | F3: ATIVO | G3: Inadimplência | H3: 45954 | I3: maretoliedu@hotmail.com | J3: 6792157907 | K3: BIFÁSICO | L3: 0.25 | M3: 319 | O3: MS | P3: RUA AIMORE DE OLIVEIRA LIMA, 835 - 14.094.85.107001 - 79920000 | Q3: 255 | R3: 325 | S3: =COUNTIFS(Faturamento!B:B,Base_Clientes[[#This Row],[INSTALAÇÃO]],Faturamento!V:V,"Atrasado") -> 2
A4: 10/10232-7 | B4: IGREJA DO EVANGELHO QUADRANGULAR | C4: 62.955.505/3932-07 | D4: ENERGISA MS | E4: APTO RATEIO | F4: ATIVO | I4: katiaconceicaogomes2020@gmail.com | J4: 67 996415566 | K4: BIFÁSICO | L4: 0.25 | M4: 302 | O4: MS | P4: RUA ONZE S/N Q 74 L 22 10.002.13.434000 - NOVA AQUIDAUANA, CEP 79200000 - AQUIDAUANA / MS | Q4: 99.833333 | R4: 99.833333 | S4: =COUNTIFS(Faturamento!B:B,Base_Clientes[[#This Row],[INSTALAÇÃO]],Faturamento!V:V,"Atrasado") -> 0
A5: 10/1035655-8 | B5: IGREJA DO EVANGELHO QUADRANGULAR | C5: 62.955.505/1822-57 | D5: ENERGISA MS | E5: APTO RATEIO | F5: ATIVO | I5: auxiliar.cedms@gmail.com | J5: 67996135721 | K5: TRIFÁSICO | L5: 0.25 | M5: 319 | O5: MS | P5: RUA ANTONIO AMARO DE MATTOS 5422 CX 02 07.010.26.205001 - VILA ROSA, CEP 79831130 - DOURADOS / MS | Q5: 453.58333 | R5: 453.58333 | S5: =COUNTIFS(Faturamento!B:B,Base_Clientes[[#This Row],[INSTALAÇÃO]],Faturamento!V:V,"Atrasado") -> 0
A6: 10/104720-8 | B6: IGREJA DO EVANGELHO QUADRANGULAR | C6: 62.955.505/0914-56 | D6: ENERGISA MS | E6: ACOMPANHAR CRÉDITO | F6: INATIVO | G6: Solicitação de distrato | I6: auxiliar.cedms@gmail.com | J6: 67991767866 | L6: 0.25 | M6: 306 | O6: MS | Q6: 136 | R6: 136 | S6: =COUNTIFS(Faturamento!B:B,Base_Clientes[[#This Row],[INSTALAÇÃO]],Faturamento!V:V,"Atrasado") -> 0
A7: 10/1081489-5 | B7: IGREJA DO EVANGELHO QUADRANGULAR | C7: 62.955.505/0169-18 | D7: ENERGISA MS | E7: APTO RATEIO | F7: ATIVO | I7: regiao351@gmail.com | J7: 67996446178 | K7: BIFÁSICO | L7: 0.25 | M7: 351 | O7: MS | P7: RUA PRUDENTE DE MORAES ALTO MARACAJU CEP 79150000 - MARACAJU / MS | Q7: 501.83333 | R7: 547.45455 | S7: =COUNTIFS(Faturamento!B:B,Base_Clientes[[#This Row],[INSTALAÇÃO]],Faturamento!V:V,"Atrasado") -> 1
A8: 10/109074-5 | B8: IGREJA DO EVANGELHO QUADRANGULAR | C8: 62.955.505/0001-67 | D8: ENERGISA MS | E8: ACOMPANHAR CRÉDITO | F8: ATIVO | G8: Inadimplência | H8: 45954 | I8: auxiliar.cedms@gmail.com | J8: 67 91751433 | K8: BIFÁSICO | L8: 0.25 | M8: 319 | O8: MS | P8: RUA QUINZE DE NOVEMBRO 2180 - CENTRO CEP 79940000 - CAARAPO / MS | Q8: 224.41667 | R8: 244.81818 | S8: =COUNTIFS(Faturamento!B:B,Base_Clientes[[#This Row],[INSTALAÇÃO]],Faturamento!V:V,"Atrasado") -> 6
A9: 10/1117293-9 | B9: IGREJA DO EVANGELHO QUADRANGULAR | C9: 62.955.505/8921-14 | D9: ENERGISA MS | E9: APTO RATEIO | F9: ATIVO | I9: pastoreliasmn@hotmail.com | J9: 67999516782 | K9: TRIFÁSICO | L9: 0.25 | M9: 362 | O9: MS | P9: AVENIDA ANTONIO JOAQUIM DE MOURA ANDRADE 2141 10 041 07 522500 - CENTRO CEP 79750000 - NOVA ANDRADINA / MS | Q9: 178.41667 | R9: 178.41667 | S9: =COUNTIFS(Faturamento!B:B,Base_Clientes[[#This Row],[INSTALAÇÃO]],Faturamento!V:V,"Atrasado") -> 1
A10: 10/1130988-7 | B10: IGREJA DO EVANGELHO QUADRANGULAR | C10: 62.955.505/0408-94 | D10: ENERGISA MS | E10: APTO RATEIO | F10: ATIVO | I10: regiao371@gmail.com | J10: 67992637973 | K10: BIFÁSICO | L10: 0.25 | M10: 371 | O10: MS | P10: RUA CAPITAO CANTALICE S/N CENTRO CEP 79280000 - PORTO MURTINHO / MS | Q10: 218.66667 | R10: 238.54545 | S10: =COUNTIFS(Faturamento!B:B,Base_Clientes[[#This Row],[INSTALAÇÃO]],Faturamento!V:V,"Atrasado") -> 0
A11: 10/113971-6 | B11: IGREJA DO EVANGELHO QUADRANGULAR | C11: 62.955.505/0156-01 | D11: ENERGISA MS | E11: ACOMPANHAR CRÉDITO | F11: INATIVO | G11: Solicitação de distrato | I11: auxiliar.cedms@gmail.com | J11: 67996575782 | K11: TRIFÁSICO | L11: 0.25 | M11: 319 | O11: MS | P11: RUA CARLOS CHAGAS 1092 05.026.05.081000 - JARDIM SAO PAULO, CEP 79700000 - FATIMA DO SUL / MS | Q11: 236.08333 | R11: 236.08333 | S11: =COUNTIFS(Faturamento!B:B,Base_Clientes[[#This Row],[INSTALAÇÃO]],Faturamento!V:V,"Atrasado") -> 0
A12: 10/1184751-4 | B12: IGREJA DO EVANGELHO QUADRANGULAR | C12: 62.955.505/1490-47 | D12: ENERGISA MS | E12: APTO RATEIO | F12: ATIVO | I12: auxiliar.cedms@gmail.com | J12: 67 96034976 | K12: TRIFÁSICO | L12: 0.25 | M12: 319 | O12: MS | P12: RUA DOM PEDRO I 1135 07.010.45.317001 - JARDIM GUANABARA, CEP 79833090 - DOURADOS / MS | Q12: 182.25 | R12: 182.25 | S12: =COUNTIFS(Faturamento!B:B,Base_Clientes[[#This Row],[INSTALAÇÃO]],Faturamento!V:V,"Atrasado") -> 0
A13: 10/1266128-6 | B13: IGREJA DO EVANGELHO QUADRANGULAR | C13: 62.955.505/3793-95 | D13: ENERGISA MS | E13: APTO RATEIO | F13: ATIVO | I13: auxiliar.cedms@gmail.com | J13: 67991306665 | K13: TRIFÁSICO | L13: 0.25 | M13: 306 | O13: MS | P13: RUA MARACANI 439 PARQUE DOS NOVOS ESTADOS CEP 79034280 - CAMPO GRANDE / MS | Q13: 365 | R13: 398.18182 | S13: =COUNTIFS(Faturamento!B:B,Base_Clientes[[#This Row],[INSTALAÇÃO]],Faturamento!V:V,"Atrasado") -> 0
A14: 10/127464-6 | B14: IGREJA DO EVANGELHO QUADRANGULAR | C14: 62.955.505/3311-98 | D14: ENERGISA MS | E14: APTO RATEIO | F14: ATIVO | I14: mariza.ieq@gmail.com | J14: 67996150274 | K14: TRIFÁSICO | L14: 0.25 | M14: 360 | O14: MS | P14: AVENIDA MATO GROSSO DO SUL 1466 CENTRO CEP 79400000 - COXIM / MS | Q14: 432.33333 | R14: 471.63636 | S14: =COUNTIFS(Faturamento!B:B,Base_Clientes[[#This Row],[INSTALAÇÃO]],Faturamento!V:V,"Atrasado") -> 0
A15: 10/1288241-1 | B15: IGREJA DO EVANGELHO QUADRANGULAR | C15: 62.955.505/3358-51 | D15: ENERGISA MS | E15: APTO RATEIO | F15: ATIVO | I15: auxiliar.cedms@gmail.com | J15: 67991133770 | K15: TRIFÁSICO | L15: 0.25 | M15: 306 | O15: MS | P15: AVENIDA TAMANDARE 1036 VILA PLANALTO CEP 79009790 - CAMPO GRANDE / MS | Q15: 192.08333 | R15: 209.54545 | S15: =COUNTIFS(Faturamento!B:B,Base_Clientes[[#This Row],[INSTALAÇÃO]],Faturamento!V:V,"Atrasado") -> 0
A16: 10/129490-9 | B16: IGREJA DO EVANGELHO QUADRANGULAR | C16: 62.955.505/4051-40 | D16: ENERGISA MS | E16: ACOMPANHAR CRÉDITO | F16: ATIVO | G16: Inadimplência | H16: 45954 | I16: regiao351@gmail.com | J16: 67996446178 | K16: BIFÁSICO | L16: 0.25 | M16: 351 | O16: MS | P16: RUA JUVIANO MEDEIROS 1239 CENTRO CEP 79130000 - RIO BRILHANTE / MS | Q16: 226.16667 | R16: 246.72727 | S16: =COUNTIFS(Faturamento!B:B,Base_Clientes[[#This Row],[INSTALAÇÃO]],Faturamento!V:V,"Atrasado") -> 1
A17: 10/135237-6 | B17: IGREJA DO EVANGELHO QUADRANGULAR | C17: 62.955.505/0800-98 | D17: ENERGISA MS | E17: APTO RATEIO | F17: ATIVO | I17: regiao351@gmail.com | J17: 67996446178 | K17: TRIFÁSICO | L17: 0.25 | M17: 351 | O17: MS | P17: RUA ROSALVO FRAGA SANTOS 60 05.031.05.383000 - VILA PRATEADA, CEP 79150000 - MARACAJU / MS | Q17: 134.36364 | R17: 134.36364 | S17: =COUNTIFS(Faturamento!B:B,Base_Clientes[[#This Row],[INSTALAÇÃO]],Faturamento!V:V,"Atrasado") -> 0
A18: 10/13786-9 | B18: IGREJA DO EVANGELHO QUADRANGULAR | C18: 62.955.505/1975-21 | D18: ENERGISA MS | E18: APTO RATEIO | F18: ATIVO | I18: regiao.357.25@gmail.com | J18: 67996266684 | K18: BIFÁSICO | L18: 0.25 | M18: 357 | O18: MS | P18: RUA MARECHAL DEODORO 118 DOM BOSCO CEP 79333080 - CORUMBA / MS | Q18: 255.16667 | R18: 278.36364 | S18: =COUNTIFS(Faturamento!B:B,Base_Clientes[[#This Row],[INSTALAÇÃO]],Faturamento!V:V,"Atrasado") -> 1
A19: 10/142353-2 | B19: IGREJA DO EVANGELHO QUADRANGULAR | C19: 62.955.505/1138-75 | D19: ENERGISA MS | E19: APTO RATEIO | F19: ATIVO | I19: odpto61@hotmail.com | J19: 67992899434 | K19: BIFÁSICO | L19: 0.25 | M19: 358 | O19: MS | P19: RUA ANTONIO JOAO 2547 CENTRO CEP 79904668 - PONTA PORA / MS | Q19: 412.33333 | R19: 449.81818 | S19: =COUNTIFS(Faturamento!B:B,Base_Clientes[[#This Row],[INSTALAÇÃO]],Faturamento!V:V,"Atrasado") -> 0
A20: 10/1433087-2 | B20: IGREJA DO EVANGELHO QUADRANGULAR | C20: 62.955.505/4194-43 | D20: ENERGISA MS | E20: ACOMPANHAR CRÉDITO | F20: INATIVO | G20: Solicitação de distrato | I20: scr_prmarcal@hotmail.com | J20: 67 91285460 | K20: TRIFÁSICO | L20: 0.25 | M20: 331 | O20: MS | Q20: 235.08333 | R20: 235.08333 | S20: =COUNTIFS(Faturamento!B:B,Base_Clientes[[#This Row],[INSTALAÇÃO]],Faturamento!V:V,"Atrasado") -> 0
A21: 10/150263-2 | B21: IGREJA DO EVANGELHO QUADRANGULAR | C21: 62.955.505/0914-56 | D21: ENERGISA MS | E21: RESCINDIDO | F21: INATIVO | G21: Solicitação de distrato | I21: região358ms@gmail.com | J21: 67992337953 | K21: MONOFÁSICO | L21: 0.25 | M21: 358 | O21: MS | Q21: 162 | R21: 162 | S21: =COUNTIFS(Faturamento!B:B,Base_Clientes[[#This Row],[INSTALAÇÃO]],Faturamento!V:V,"Atrasado") -> 1
A22: 10/15297-5 | B22: IGREJA DO EVANGELHO QUADRANGULAR | C22: 62.955.505/3124-87 | D22: ENERGISA MS | E22: APTO RATEIO | F22: ATIVO | I22: regiao.357.25@gmail.com | J22: 67996266684 | K22: TRIFÁSICO | L22: 0.25 | M22: 357 | O22: MS | P22: RUA REPUBLICA DA BOLIVIA, 32 DOM BOSCO CORUMBA / MS | Q22: 453.91667 | R22: 495.18182 | S22: =COUNTIFS(Faturamento!B:B,Base_Clientes[[#This Row],[INSTALAÇÃO]],Faturamento!V:V,"Atrasado") -> 0
A23: 10/1548741-6 | B23: IGREJA DO EVANGELHO QUADRANGULAR | C23: 62.955.505/0847-51 | D23: ENERGISA MS | E23: APTO RATEIO | F23: ATIVO | I23: ieqreg349cassi@gmail.com | J23: 67 81355403 | K23: MONOFÁSICO | L23: 0.25 | M23: 349 | O23: MS | P23: RUA JOSE AGI 651 12.014.07.803500 - JARDIM AMERICA CEP 79500000 - PARANAIBA / MS | Q23: 156.25 | R23: 156.25 | S23: =COUNTIFS(Faturamento!B:B,Base_Clientes[[#This Row],[INSTALAÇÃO]],Faturamento!V:V,"Atrasado") -> 1
A24: 10/156956-5 | B24: IGREJA DO EVANGELHO QUADRANGULAR | C24: 62.955.505/0153-50 | D24: ENERGISA MS | E24: APTO RATEIO | F24: ATIVO | I24: quadrangular994@gmail.com | J24: 67 998338301 | K24: TRIFÁSICO | L24: 0.25 | M24: 994 | O24: MS | P24: RUA GENERAL CAMARA 561 14.036.03.163000 - CENTRO, CEP 79990000 - AMAMBAI / MS | Q24: 362.41667 | R24: 362.41667 | S24: =COUNTIFS(Faturamento!B:B,Base_Clientes[[#This Row],[INSTALAÇÃO]],Faturamento!V:V,"Atrasado") -> 0
A25: 10/162736-3 | B25: IGREJA DO EVANGELHO QUADRANGULAR | C25: 62.955.505/1973-60 | D25: ENERGISA MS | E25: ACOMPANHAR CRÉDITO | F25: ATIVO | G25: Inadimplência | H25: 45954 | I25: mariza.ieq@gmail.com | J25: 67996150274 | K25: TRIFÁSICO | L25: 0.25 | M25: 360 | O25: MS | P25: RUA SANTOS DUMONT 310 15.037.01.489000 - CENTRO CEP 79480000 - RIO VERDE DE MATO GROSSO / MS | Q25: 185.66667 | R25: 185.66667 | S25: =COUNTIFS(Faturamento!B:B,Base_Clientes[[#This Row],[INSTALAÇÃO]],Faturamento!V:V,"Atrasado") -> 5
A26: 10/1672452-8 | B26: IGREJA DO EVANGELHO QUADRANGULAR | C26: 62.955.505/0172-13 | D26: ENERGISA MS | E26: APTO RATEIO | F26: ATIVO | I26: regiao371@gmail.com | J26: 67992637973 | K26: TRIFÁSICO | L26: 0.25 | M26: 371 | O26: MS | P26: RUA N SRA DA PENHA, 540, CENTRO, BONITO-MS | Q26: 418.16667 | R26: 418.16667 | S26: =COUNTIFS(Faturamento!B:B,Base_Clientes[[#This Row],[INSTALAÇÃO]],Faturamento!V:V,"Atrasado") -> 0
A27: 10/1674177-9 | B27: IGREJA DO EVANGELHO QUADRANGULAR | C27: 62.955.505/0161-60 | D27: ENERGISA MS | E27: APTO RATEIO | F27: ATIVO | I27: 3ieqant302@gmail.com | J27: 6784548587 | K27: TRIFÁSICO | L27: 0.25 | M27: 302 | O27: MS | P27: RUA JOAO LEITE RIBEIRO 1636 CENTRO CEP 79210000 - ANASTACIO / MS | Q27: 218.66667 | R27: 393 | S27: =COUNTIFS(Faturamento!B:B,Base_Clientes[[#This Row],[INSTALAÇÃO]],Faturamento!V:V,"Atrasado") -> 0
A28: 10/1695011-5 | B28: IGREJA DO EVANGELHO QUADRANGULAR | C28: 62.955.505/4612-10 | D28: ENERGISA MS | E28: APTO RATEIO | F28: ATIVO | I28: auxiliar.cedms@gmail.com | J28: 67991767866 | K28: TRIFÁSICO | L28: 0.25 | M28: 306 | O28: MS | P28: RUA JOSE RICARTES DE OLIVEIRA, 56, SANTO ANDRE, RIBAS DO RIO PARDO | Q28: 511.41667 | R28: 511.41667 | S28: =COUNTIFS(Faturamento!B:B,Base_Clientes[[#This Row],[INSTALAÇÃO]],Faturamento!V:V,"Atrasado") -> 0
A29: 10/1698130-0 | B29: IGREJA DO EVANGELHO QUADRANGULAR | C29: 62.955.505/4612-10 | D29: ENERGISA MS | E29: APTO RATEIO | F29: ATIVO | I29: auxiliar.cedms@gmail.com | J29: 67991767866 | K29: TRIFÁSICO | L29: 0.25 | M29: 306 | O29: MS | P29: RUA JOSE RICARTES DE OLIVEIRA, 56, SANTO ANDRE, RIBAS DO RIO PARDO | Q29: 279.08333 | R29: 279.08333 | S29: =COUNTIFS(Faturamento!B:B,Base_Clientes[[#This Row],[INSTALAÇÃO]],Faturamento!V:V,"Atrasado") -> 0
A30: 10/175073-6 | B30: IGREJA DO EVANGELHO QUADRANGULAR | C30: 62.955.505/1344-49 | D30: ENERGISA MS | E30: APTO RATEIO | F30: ATIVO | I30: pastoreliasmn@hotmail.com | J30: 67999516782 | K30: BIFÁSICO | L30: 0.25 | M30: 362 | O30: MS | P30: RUA MIGUEL MARCHETTI 149 ITAPOA CEP 79740000 - IVINHEMA / MS | Q30: 129.08333 | R30: 140.81818 | S30: =COUNTIFS(Faturamento!B:B,Base_Clientes[[#This Row],[INSTALAÇÃO]],Faturamento!V:V,"Atrasado") -> 1
A31: 10/18015-8 | B31: IGREJA DO EVANGELHO QUADRANGULAR | C31: 62.955.505/0160-80 | D31: ENERGISA MS | E31: APTO RATEIO | F31: ATIVO | I31: regiao.357.25@gmail.com | J31: 67996266684 | K31: TRIFÁSICO | L31: 0.25 | M31: 357 | O31: MS | P31: RUA JOAQUIM MURTINHO, 72, CENTRO, CORUMBA-MS | Q31: 958.25 | R31: 958.25 | S31: =COUNTIFS(Faturamento!B:B,Base_Clientes[[#This Row],[INSTALAÇÃO]],Faturamento!V:V,"Atrasado") -> 1
A32: 10/191945-5 | B32: IGREJA DO EVANGELHO QUADRANGULAR | C32: 62.955.505/2157-91 | D32: ENERGISA MS | E32: APTO RATEIO | F32: ATIVO | I32: ieqreg349cassi@gmail.com | J32: 67 81355403 | K32: TRIFÁSICO | L32: 0.25 | M32: 349 | O32: MS | P32: RUA GOIAS, 1000, CENTRO, CASSILANDIA-MS | Q32: 802.5 | R32: 802.5 | S32: =COUNTIFS(Faturamento!B:B,Base_Clientes[[#This Row],[INSTALAÇÃO]],Faturamento!V:V,"Atrasado") -> 0
A33: 10/1939035-0 | B33: IGREJA DO EVANGELHO QUADRANGULAR | C33: 62.955.505/4194-43 | D33: ENERGISA MS | E33: APTO RATEIO | F33: ATIVO | I33: scr_prmarcal@hotmail.com | J33: 67 91285460 | K33: BIFÁSICO | L33: 0.25 | M33: 331 | O33: MS | P33: RUA NOVE, 121 / QD E LT 1B - RESIDENCIAL MODELO II - BATAGUASSU/MS | Q33: 372.25 | R33: 372.25 | S33: =COUNTIFS(Faturamento!B:B,Base_Clientes[[#This Row],[INSTALAÇÃO]],Faturamento!V:V,"Atrasado") -> 0
A34: 10/202838-9 | B34: IGREJA DO EVANGELHO QUADRANGULAR | C34: 62.955.505/0164-03 | D34: ENERGISA MS | E34: APTO RATEIO | F34: ATIVO | I34: regiao371@gmail.com | J34: 67992637973 | K34: TRIFÁSICO | L34: 0.25 | M34: 371 | O34: MS | P34: RUA GUANABARA, 146 - 17.047.05.488000 TELEMETRIA - 79240000 VILA ANGELICA I JARDIM (AG: 47) | Q34: 796.66667 | R34: 796.66667 | S34: =COUNTIFS(Faturamento!B:B,Base_Clientes[[#This Row],[INSTALAÇÃO]],Faturamento!V:V,"Atrasado") -> 0
A35: 10/218777-1 | B35: IGREJA DO EVANGELHO QUADRANGULAR | C35: 62.955.505/0170-51 | D35: ENERGISA MS | E35: APTO RATEIO | F35: ATIVO | I35: auxiliar.cedms@gmail.com | J35: 67999031330 | K35: BIFÁSICO | L35: 0.25 | M35: 306 | O35: MS | P35: RUA AMAZONAS 171 11.053.01.501000 - CENTRO CEP 79170000 - SIDROLANDIA / MS | Q35: 153.91667 | R35: 153.91667 | S35: =COUNTIFS(Faturamento!B:B,Base_Clientes[[#This Row],[INSTALAÇÃO]],Faturamento!V:V,"Atrasado") -> 0
A36: 10/226667-4 | B36: IGREJA DO EVANGELHO QUADRANGULAR | C36: 62.955.505/0408-94 | D36: ENERGISA MS | E36: APTO RATEIO | F36: ATIVO | I36: regiao371@gmail.com | J36: 67992637973 | K36: BIFÁSICO | L36: 0.25 | M36: 371 | O36: MS | P36: VISCONDE DE TAUNAY, 2925 CASA 1 X - CEP:79260000 - CENTRO - BELA VISTA MS | Q36: 157.66667 | R36: 157.66667 | S36: =COUNTIFS(Faturamento!B:B,Base_Clientes[[#This Row],[INSTALAÇÃO]],Faturamento!V:V,"Atrasado") -> 0
A37: 10/237441-1 | B37: IGREJA DO EVANGELHO QUADRANGULAR | C37: 62.955.505/0172-13 | D37: ENERGISA MS | E37: APTO RATEIO | F37: ATIVO | I37: regiao371@gmail.com | J37: 67992637973 | K37: TRIFÁSICO | L37: 0.25 | M37: 371 | O37: MS | P37: AVENIDA HERON DO COUTO S/N 14.061.05.032000 - MARAMBA CEP 79290000 - BONITO / MS | Q37: 166.66667 | R37: 166.66667 | S37: =COUNTIFS(Faturamento!B:B,Base_Clientes[[#This Row],[INSTALAÇÃO]],Faturamento!V:V,"Atrasado") -> 0
A38: 10/239312-2 | B38: IGREJA DO EVANGELHO QUADRANGULAR | C38: 62.955.505/0165-94 | D38: ENERGISA MS | E38: APTO RATEIO | F38: ATIVO | I38: ieqnioaque@gmail.com | J38: 67996711972 | K38: BIFÁSICO | L38: 0.25 | M38: 302 | O38: MS | P38: RUA TREZE DE MAIO 692 CENTRO CEP 79220000 - NIOAQUE / MS | Q38: 263.41667 | R38: 287.36364 | S38: =COUNTIFS(Faturamento!B:B,Base_Clientes[[#This Row],[INSTALAÇÃO]],Faturamento!V:V,"Atrasado") -> 0
A39: 10/24514-2 | B39: IGREJA DO EVANGELHO QUADRANGULAR | C39: 62.955.505/1570-66 | D39: ENERGISA MS | E39: APTO RATEIO | F39: ATIVO | I39: regiao.357.25@gmail.com | J39: 67996266684 | K39: TRIFÁSICO | L39: 0.25 | M39: 357 | O39: MS | P39: RUA SAO PAULO 36 CRISTO REDENTOR CEP 79311040 - CORUMBA / MS | Q39: 297.66667 | R39: 324.72727 | S39: =COUNTIFS(Faturamento!B:B,Base_Clientes[[#This Row],[INSTALAÇÃO]],Faturamento!V:V,"Atrasado") -> 1
A40: 10/252817-2 | B40: IGREJA DO EVANGELHO QUADRANGULAR | C40: 62.955.505/2740-20 | D40: ENERGISA MS | E40: APTO RATEIO | F40: ATIVO | I40: regiao371@gmail.com | J40: 67992637973 | K40: TRIFÁSICO | L40: 0.25 | M40: 371 | O40: MS | P40: RUA JOAO MARTINS LEITE 200 CENTRO CEP 79270000 - CARACOL / MS | Q40: 352.83333 | R40: 384.90909 | S40: =COUNTIFS(Faturamento!B:B,Base_Clientes[[#This Row],[INSTALAÇÃO]],Faturamento!V:V,"Atrasado") -> 0
A41: 10/257864-9 | B41: IGREJA DO EVANGELHO QUADRANGULAR | C41: 62.955.505/1821-76 | D41: ENERGISA MS | E41: ACOMPANHAR CRÉDITO | F41: ATIVO | G41: Inadimplência | H41: 45954 | J41: 67981311823 | K41: BIFÁSICO | L41: 0.25 | M41: 362 | O41: MS | P41: RUA SEN TEOTONIO VILELA 427 11.074.05.148000 - CENTRO, CEP 79965000 - ITAQUIRAI / MS | Q41: 153.91667 | R41: 153.91667 | S41: =COUNTIFS(Faturamento!B:B,Base_Clientes[[#This Row],[INSTALAÇÃO]],Faturamento!V:V,"Atrasado") -> 9
...

Sheet Inadimplência
A1: Status Pagamento | B1: (Vários itens)
A3: Mês Ref | B3: Qted | C3: Total Emitido (R$) | D3: Total Pago (R$) | E3: Valor em Acordo | F3: Valor Inadimplente | G3: % inadimplência
A4: 45658 | B4: 84 | C4: 19964.24 | D4: 19059.44 | E4: =SUMIFS(Faturamento!R:R,Faturamento!G:G,Inadimplência!A4,Faturamento!V:V,"Acordo") -> 0 | F4: =C4-D4-E4 -> 904.8 | G4: =F4/C4 -> 0.045321034
A5: 45689 | B5: 50 | C5: 16003.59 | D5: 15264.88 | E5: =SUMIFS(Faturamento!R:R,Faturamento!G:G,Inadimplência!A5,Faturamento!V:V,"Acordo") -> 0 | F5: =C5-D5-E5 -> 738.71 | G5: =F5/C5 -> 0.046159018
A6: 45717 | B6: 55 | C6: 17915 | D6: 17007.83 | E6: =SUMIFS(Faturamento!R:R,Faturamento!G:G,Inadimplência!A6,Faturamento!V:V,"Acordo") -> 0 | F6: =C6-D6-E6 -> 907.17 | G6: =F6/C6 -> 0.050637455
A7: 45748 | B7: 86 | C7: 18900.91 | D7: 16189.3 | E7: =SUMIFS(Faturamento!R:R,Faturamento!G:G,Inadimplência!A7,Faturamento!V:V,"Acordo") -> 175.21 | F7: =C7-D7-E7 -> 2536.4 | G7: =F7/C7 -> 0.1341946
A8: 45778 | B8: 83 | C8: 16645.9 | D8: 14193.639 | E8: =SUMIFS(Faturamento!R:R,Faturamento!G:G,Inadimplência!A8,Faturamento!V:V,"Acordo") -> 0 | F8: =C8-D8-E8 -> 2452.261 | G8: =F8/C8 -> 0.14731922
A9: 45809 | B9: 63 | C9: 9822.37 | D9: 9532.5733 | E9: =SUMIFS(Faturamento!R:R,Faturamento!G:G,Inadimplência!A9,Faturamento!V:V,"Acordo") -> 0 | F9: =C9-D9-E9 -> 289.79667 | G9: =F9/C9 -> 0.029503742
A10: 45839 | B10: 75 | C10: 12120.21 | D10: 12060.14 | E10: =SUMIFS(Faturamento!R:R,Faturamento!G:G,Inadimplência!A10,Faturamento!V:V,"Acordo") -> 161.56 | F10: =C10-D10-E10 -> -101.49 | G10: 0
A11: 45870 | B11: 78 | C11: 14372.97 | D11: 14030.1 | E11: =SUMIFS(Faturamento!R:R,Faturamento!G:G,Inadimplência!A11,Faturamento!V:V,"Acordo") -> 172.03 | F11: =C11-D11-E11 -> 170.84 | G11: =F11/C11 -> 0.0118862
A12: 45901 | B12: 79 | C12: 18122.97 | D12: 17328.501 | E12: =SUMIFS(Faturamento!R:R,Faturamento!G:G,Inadimplência!A12,Faturamento!V:V,"Acordo") -> 0 | F12: =C12-D12-E12 -> 794.46947 | G12: =F12/C12 -> 0.043837708
A13: 45931 | B13: 85 | C13: 23671.21 | D13: 22313.22 | E13: =SUMIFS(Faturamento!R:R,Faturamento!G:G,Inadimplência!A13,Faturamento!V:V,"Acordo") -> 0 | F13: =C13-D13-E13 -> 1357.99 | G13: =F13/C13 -> 0.057368846
A14: 45962 | B14: 87 | C14: 28544.62 | D14: 18614.41 | E14: =SUMIFS(Faturamento!R:R,Faturamento!G:G,Inadimplência!A14,Faturamento!V:V,"Acordo") -> 0 | F14: =C14-D14-E14 -> 9930.21 | G14: =F14/C14 -> 0.34788377
A15: Total Geral | B15: 825 | C15: 196083.99 | D15: 175594.03 | E15: =SUM(E4:E12) -> 508.8 | F15: =SUM(F4:F12) -> 8692.9571 | G15: =AVERAGE(G4:G12) -> 0.056539886
A17: Mês Ref | B17: % atual | C17: % anterior | D17: Redução
A18: 45658 | B18: 0.045321034 | C18: 0.045321034 | D18: =B18-C18 -> 0
A19: 45689 | B19: 0.046159018 | C19: 0.046159018 | D19: =B19-C19 -> 0
A20: 45717 | B20: 0.050637455 | C20: 0.050637455 | D20: =B20-C20 -> 0
A21: 45748 | B21: 0.13002646 | C21: 0.13883247 | D21: =B21-C21 -> -0.0088060106
A22: 45778 | B22: 0.16754162 | C22: 0.17203275 | D22: =B22-C22 -> -0.004491136
A23: 45809 | B23: 0.029503742 | C23: 0.035513832 | D23: =B23-C23 -> -0.0060100906
A24: 45839 | B24: 0 | C24: 0.005212781 | D24: =B24-C24 -> -0.005212781
A25: 45870 | B25: 0.01543244 | C25: 0.01543244 | D25: =B25-C25 -> -1.2490009e-16
A26: 45901 | B26: 0.043838 | C26: 0.065625005 | D26: =B26-C26 -> -0.021787005
A27: 45931 | B27: 0.139392 | C27: 0.14 | D27: =B27-C27 -> -0.000608
A29: Representatividade Inadimplencia por região
A31: Status Pagamento | B31: Atrasado
A33: Região | B33: % inadimplente
A34: Total Geral | B34: #DIV/0!

Sheet Processos
A1: Processos EGS: | B1: Gestão de Energia | C1: Atendimento
A2: 1. Rateio | B2: to do: tentar internalizar esse processo | C2: envio base para Livia dia 20
A3: 2. Alterações contratuais | B3: verificação da base antes de envio do rateio | C3: alteração direta na base
A4: 3. Acesso às faturas | B4: Thiago responsável | C4: Acompanhamento dos recebimentos
A5: 4. Entrada / Saída unidade | B5: verificação da base antes de envio do rateio | C5: indicar na base / Prazo até 90 para retirada total /cobrança de crédito acumulado
A6: 5. Faturamento | B6: Liberação relatório 1 dia útil antes do dia 10 | C6: Faturamento todo dia 10
A7: 6. Pagamento Inadimplência | B7: to do: Inclusão no relatório da coluna "Calculo HUBE final sem desconto" | C7: Realizar as cobranças com base no boleto sem desconto
A8: 7. Conciliação pagamento inadimplencia | B8: Utilizar a base de clientes - aba Faturamento | C8: utilizar extrato Ictus para atualização

Sheet Contatos - Ref.Jun-25
A1: CONTATO | B1: RAZÃO | C1: SOLUÇÃO | D1: RESPONSÁVEL UC | E1: RESPONSÁVEL REGIONAL | F1: 1- Reforçar se o e-mail de recebimento das faturas está correto e se recebeu a fatura enviada dia 21/07. 2- Informar o nosso e-mail de atendimento (atendimento@egsenergia.com.br), que é o mesmo que foi encaminhada a fatura Jun/25. 3- Comunicar que em breve disponibilizaremos o canal de WhatsApp (Executivo de Contas - Adriano)
A2: 67991120875 | B2: IGREJA DO EVANGELHO QUADRANGULAR | C2: EGS ENERGIA | E2: Adriana
A3: 67 996469842 | B3: IGREJA DO EVANGELHO QUADRANGULAR | C3: EGS ENERGIA | E3: Adriana
A4: 67992637973 | B4: IGREJA DO EVANGELHO QUADRANGULAR | C4: EGS ENERGIA | E4: Adriana
A5: 67996266684 | B5: IGREJA DO EVANGELHO QUADRANGULAR | C5: EGS ENERGIA | E5: Adriana
A6: 67 81355403 | B6: IGREJA DO EVANGELHO QUADRANGULAR | C6: EGS ENERGIA | E6: Adriana
A7: 67 992466753 | B7: IGREJA DO EVANGELHO QUADRANGULAR | C7: EGS ENERGIA | E7: Adriana
A8: 67 91285460 | B8: IGREJA DO EVANGELHO QUADRANGULAR | C8: EGS ENERGIA | E8: Adriana
A9: 46 999066691 | B9: IGREJA DO EVANGELHO QUADRANGULAR | C9: EGS ENERGIA | E9: Adriana
A10: 67996446178 | B10: IGREJA DO EVANGELHO QUADRANGULAR | C10: EGS ENERGIA | E10: Adriana
A11: 67996135721 | B11: IGREJA DO EVANGELHO QUADRANGULAR | C11: EGS ENERGIA | E11: Adriana
A12: 67 992321318 | B12: IGREJA DO EVANGELHO QUADRANGULAR | C12: EGS ENERGIA | E12: Adriana
A13: 67 998338301 | B13: IGREJA DO EVANGELHO QUADRANGULAR | C13: EGS ENERGIA | E13: Adriana
A14: 67991767866 | B14: IGREJA DO EVANGELHO QUADRANGULAR | C14: EGS ENERGIA | E14: Adriana
A15: 67 992158055 | B15: IGREJA DO EVANGELHO QUADRANGULAR | C15: EGS ENERGIA | E15: Adriana
A16: 67992337953 | B16: IGREJA DO EVANGELHO QUADRANGULAR | C16: EGS ENERGIA | E16: Adriana
A17: 67996575782 | B17: IGREJA DO EVANGELHO QUADRANGULAR | C17: EGS ENERGIA | E17: Adriana
A18: 67 96034976 | B18: IGREJA DO EVANGELHO QUADRANGULAR | C18: EGS ENERGIA | E18: Adriana
A19: 67999516782 | B19: IGREJA DO EVANGELHO QUADRANGULAR | C19: EGS ENERGIA | E19: Adriana
A20: 67 92480766 | B20: IGREJA DO EVANGELHO QUADRANGULAR | C20: EGS ENERGIA | E20: Adriana
A21: 67996150274 | B21: IGREJA DO EVANGELHO QUADRANGULAR | C21: EGS ENERGIA | E21: Adriana
A22: 67999031330 | B22: IGREJA DO EVANGELHO QUADRANGULAR | C22: EGS ENERGIA | E22: Adriana
A23: 67993496482 | B23: IGREJA DO EVANGELHO QUADRANGULAR | C23: EGS ENERGIA | E23: Adriana
A24: 67 996415566 | B24: IGREJA DO EVANGELHO QUADRANGULAR | C24: EGS ENERGIA | E24: Adriana
A25: 67999159477 | B25: IGREJA DO EVANGELHO QUADRANGULAR | C25: EGS ENERGIA | E25: Adriana
A26: 67991120875 | B26: IGREJA DO EVANGELHO QUADRANGULAR | C26: EGS ENERGIA | E26: Adriana
A27: 67991162146 | B27: IGREJA DO EVANGELHO QUADRANGULAR | C27: EGS ENERGIA | E27: Adriana
A28: 67 999373813 | B28: IGREJA DO EVANGELHO QUADRANGULAR | C28: EGS ENERGIA | E28: Adriana
A29: 67992899434 | B29: IGREJA DO EVANGELHO QUADRANGULAR | C29: EGS ENERGIA | E29: Adriana
A30: 67992021114 | B30: IGREJA DO EVANGELHO QUADRANGULAR | C30: EGS ENERGIA | E30: Adriana
A31: 67 992319530 | B31: IGREJA DO EVANGELHO QUADRANGULAR | C31: EGS ENERGIA | E31: Adriana
A32: 67998363594 | B32: IGREJA DO EVANGELHO QUADRANGULAR | C32: EGS ENERGIA | E32: Adriana
A33: 6796411024 | B33: IGREJA DO EVANGELHO QUADRANGULAR | C33: EGS ENERGIA | E33: Adriana
A34: 67999361728 | B34: IGREJA DO EVANGELHO QUADRANGULAR | C34: EGS ENERGIA | E34: Adriana
A35: 67991060202 | B35: IGREJA DO EVANGELHO QUADRANGULAR | C35: EGS ENERGIA | E35: Adriana
A36: 67999998719 | B36: IGREJA DO EVANGELHO QUADRANGULAR | C36: EGS ENERGIA | E36: Adriana
A37: 67 992491551 | B37: IGREJA DO EVANGELHO QUADRANGULAR | C37: EGS ENERGIA | E37: Adriana
A38: 67 993047635 | B38: IGREJA DO EVANGELHO QUADRANGULAR | C38: EGS ENERGIA | E38: Adriana
A39: 67996071169 | B39: IGREJA DO EVANGELHO QUADRANGULAR | C39: EGS ENERGIA | E39: Adriana
A40: 67996859014 | B40: IGREJA DO EVANGELHO QUADRANGULAR | C40: EGS ENERGIA | E40: Adriana
...

Sheet Faturamento
A1: Região | B1: Instalação | C1: Telefone | D1: CNPJ | E1: Distribuidora | F1: Razão Social | G1: Referência | H1: COD | I1: Fatura Disco Disponível? | J1: Créd. Consumido | K1: CUSTO_S_GD | L1: CUSTO_C_GD | M1: Status Faturamento | N1: Valor sem desconto | O1: Valor liberado | P1: Data emissão | Q1: Data Vencimento | R1: Valor emitido | S1: Motivo não emissão | T1: COD VALOR EMITIDO | U1: COD BOLETO | V1: Status Pagamento | W1: Valor Pago | X1: Multa/Juros | Y1: Data Pagamento | Z1: Estágio da Cobrança | AA1: CLIENTE (somente números) | AB1: CANAL (somente números) | AC1: NOME OU RAZÃO SOCIAL DO PAGADOR | AD1: CPF/CNPJ DO PAGADOR (digitar somente números entre apóstrofos ( ' ' )) | AE1: VALOR DO BOLETO (número com centavos separado por vírgula) | AF1: DATA DE VENCIMENTO (dd/mm/aaaa) | AG1: TEXTO QUE APARECERÁ NO CAMPO "INSTRUÇÕES" (opcional) | AH1: E-MAIL DO PAGADOR | AI1: Obs Planilha Rubia
A2: =VLOOKUP(B2,base!A:M,11,FALSE) -> TRIFÁSICO | B2: 10/237441-1 | C2: 0 | D2: 62955505017213 | E2: energisa_ms | F2: Igreja do Evangelho Quadrangular | G2: 45901 | H2: =Faturamento!$B836&Faturamento!$G836 -> 10/2338577-645658 | I2: SIM | J2: 0 | M2: Não emitido | N2: 0 | S2: Sem valor liberado para emissão | T2: 62955505017213 | V2: Não faturado | X2: =IF(Faturamento!$V879="Pago",IFERROR(W2-R2,0),0) -> 0
A3: =VLOOKUP(B3,base!A:M,11,FALSE) -> TRIFÁSICO | B3: 10/135237-6 | C3: 0 | D3: 62955505080098 | E3: energisa_ms | F3: Igreja do Evangelho Quadrangular | G3: 45901 | H3: =Faturamento!$B842&Faturamento!$G842 -> 10/142353-245689 | I3: SIM | J3: 0 | M3: Não emitido | N3: 0 | S3: Sem valor liberado para emissão | T3: 62955505080098 | V3: Não faturado | X3: =IF(Faturamento!$V880="Pago",IFERROR(W3-R3,0),0) -> 0
A4: =VLOOKUP(B4,base!A:M,11,FALSE) -> TRIFÁSICO | B4: 10/512142-1 | C4: Solicitação de distrato | D4: 62955505189340 | E4: energisa_ms | F4: Igreja do Evangelho Quadrangular | G4: 45901 | H4: =Faturamento!$B879&Faturamento!$G879 -> 10/104720-845717 | I4: SIM | J4: 0 | M4: Não emitido | N4: 0 | S4: Sem valor liberado para emissão | T4: 62955505189340 | V4: Não faturado | X4: =IF(Faturamento!$V888="Pago",IFERROR(W4-R4,0),0) -> 0
A5: =VLOOKUP(B5,base!A:M,11,FALSE) -> BIFÁSICO | B5: 10/31292-6 | C5: Solicitação de distrato | D5: 62955505016080 | E5: energisa_ms | F5: Igreja do Evangelho Quadrangular | G5: 45901 | H5: =Faturamento!$B883&Faturamento!$G883 -> 10/1081489-545717 | I5: SIM | J5: 0 | M5: Não emitido | N5: 0 | S5: Sem valor liberado para emissão | T5: 62955505016080 | V5: Não faturado | X5: =IF(Faturamento!$V889="Pago",IFERROR(W5-R5,0),0) -> 0
A6: =VLOOKUP(B6,base!A:M,11,FALSE) -> TRIFÁSICO | B6: 10/3054052-0 | C6: 0 | D6: 62955505312487 | E6: energisa_ms | F6: Igreja do Evangelho Quadrangular | G6: 45901 | H6: =Faturamento!$B888&Faturamento!$G888 -> 10/69319-245717 | I6: SIM | J6: 0 | M6: Não emitido | N6: 0 | S6: Sem valor liberado para emissão | T6: 62955505312487 | V6: Não faturado | X6: =IF(Faturamento!$V890="Pago",IFERROR(W6-R6,0),0) -> 0
A7: =VLOOKUP(B7,base!A:M,11,FALSE) -> TRIFÁSICO | B7: 10/505854-0 | C7: 0 | D7: 62955505887382 | E7: energisa_ms | F7: Igreja do Evangelho Quadrangular | G7: 45901 | H7: =Faturamento!$B890&Faturamento!$G890 -> 10/3139326-745717 | I7: SIM | J7: 0 | M7: Não emitido | N7: 0 | S7: Sem valor liberado para emissão | T7: 62955505887382 | V7: Não faturado | X7: =IF(Faturamento!$V892="Pago",IFERROR(W7-R7,0),0) -> 0
A8: =VLOOKUP(B8,base!A:M,11,FALSE) -> TRIFÁSICO | B8: 10/364440-8 | C8: 67991120875 | D8: 62955505015199 | E8: energisa_ms | F8: Igreja do Evangelho Quadrangular | G8: 45839 | H8: =Faturamento!$B619&Faturamento!$G619 -> 10/175073-645809 | I8: SIM | J8: 2565 | K8: 3099.7895 | L8: 2415.3816 | M8: =IF(Faturamento!$S619<>"","Não emitido",IF(Faturamento!$I619="NÃO","Pendente Fatura", IF(Faturamento!$R619<>"","Aprovado",IF(Faturamento!$O619<>0,"Pendente Emissão","Processo de Calculo")))) -> Aprovado | N8: 3021.3295 | O8: 2336.92 | P8: 45910 | Q8: 45920 | R8: 2336.92 | T8: 629555050151992336,92 | U8: 09/00012683468-6 | V8: Pago | W8: 2336.92 | X8: =IF(Faturamento!$V829="Pago",IFERROR(W8-R8,0),0) -> 0
A9: =VLOOKUP(B9,base!A:M,11,FALSE) -> TRIFÁSICO | B9: 10/364440-8 | C9: Inadimplência | D9: 62955505015199 | E9: energisa_ms | F9: Igreja do Evangelho Quadrangular | G9: 45870 | H9: =Faturamento!$B712&Faturamento!$G712 -> 10/24514-245839 | I9: SIM | J9: 2565 | K9: 3108.5835 | L9: 2433.0722 | M9: =IF(Faturamento!$S712<>"","Não emitido",IF(Faturamento!$I712="NÃO","Pendente Fatura", IF(Faturamento!$R712<>"","Aprovado",IF(Faturamento!$O712<>0,"Pendente Emissão","Processo de Calculo")))) -> Aprovado | N9: 2989.5035 | O9: 2313.99 | P9: 45910 | Q9: 45920 | R9: 2313.99 | T9: 629555050151992313,99 | U9: 09/00012749632-9 | V9: Pago | W9: 2313.99 | X9: =IF(Faturamento!$V828="Pago",IFERROR(W9-R9,0),0) -> 0
A10: =VLOOKUP(B10,base!A:M,11,FALSE) -> TRIFÁSICO | B10: 10/364440-8 | C10: Inadimplência | D10: 62955505015199 | E10: energisa_ms | F10: Igreja do Evangelho Quadrangular | G10: 45901 | H10: =Faturamento!$B804&Faturamento!$G804 -> 10/2605731-545627 | I10: SIM | J10: 2565 | K10: 3219.954 | L10: 2387.591 | M10: Aprovado | N10: 3099.134 | O10: 2266.77 | P10: 45933 | Q10: 45943 | R10: =O10 -> 2266.77 | T10: 629555050151992266,77 | U10: 09/00012851397-3 | V10: Pago | W10: =R10 -> 2266.77 | X10: =IF(Faturamento!$V827="Pago",IFERROR(W10-R10,0),0) -> 0
A11: =VLOOKUP(B11,base!A:M,11,FALSE) -> TRIFÁSICO | B11: 10/364440-8 | C11: 67991120875 | D11: 62955505015199 | E11: energisa_ms | F11: Igreja do Evangelho Quadrangular | G11: 45809 | H11: =Faturamento!$B530&Faturamento!$G530 -> 10/395471-645658 | I11: SIM | J11: 2579 | K11: 3065.79 | L11: 2361.0523 | M11: =IF(Faturamento!$S530<>"","Não emitido",IF(Faturamento!$I530="NÃO","Pendente Fatura", IF(Faturamento!$R530<>"","Aprovado",IF(Faturamento!$O530<>0,"Pendente Emissão","Processo de Calculo")))) -> Aprovado | N11: 2970.39 | O11: 2227.79 | P11: 45860 | Q11: 45871 | R11: 2227.79 | T11: 629555050151992227,79 | U11: 09/00012472737-9 | V11: Pago | W11: 2227.79 | X11: =IF(Faturamento!$V826="Pago",IFERROR(W11-R11,0),0) -> 0 | Y11: 05/08/2025
A12: =VLOOKUP(B12,base!A:M,11,FALSE) -> TRIFÁSICO | B12: 10/5202-7 | C12: 67 996469842 | D12: 62955505393207 | E12: energisa_ms | F12: Igreja do Evangelho Quadrangular | G12: 45717 | H12: =Faturamento!$B240&Faturamento!$G240 -> 10/63920-345931 | I12: SIM | J12: 2733 | K12: 3308.3 | L12: 2597.8525 | M12: =IF(Faturamento!$S240<>"","Não emitido",IF(Faturamento!$I240="NÃO","Pendente Fatura", IF(Faturamento!$R240<>"","Aprovado",IF(Faturamento!$O240<>0,"Pendente Emissão","Processo de Calculo")))) -> Aprovado | N12: 2841.79 | O12: 2131.34 | R12: 2131.34 | T12: 629555053932072131,34 | V12: Pago | W12: 2131.34 | X12: =IF(Faturamento!$V825="Pago",IFERROR(W12-R12,0),0) -> 0 | AI12: =VLOOKUP(B12,'[1]Conciliação - 032025'!$A:$L,12,FALSE) -> DEPÓSITO UNIFICADO ITAU - R$3.541,82 03/06/2025
A13: =VLOOKUP(B13,base!A:M,11,FALSE) -> TRIFÁSICO | B13: 10/364440-8 | C13: 67991120875 | D13: 62955505015199 | E13: energisa_ms | F13: Igreja do Evangelho Quadrangular | G13: 45748 | H13: =Faturamento!$B336&Faturamento!$G336 -> 10/129490-945717 | I13: SIM | J13: 2722 | K13: 3042.89 | L13: 2336.3525 | M13: =IF(Faturamento!$S336<>"","Não emitido",IF(Faturamento!$I336="NÃO","Pendente Fatura", IF(Faturamento!$R336<>"","Aprovado",IF(Faturamento!$O336<>0,"Pendente Emissão","Processo de Calculo")))) -> Aprovado | N13: 2826.15 | O13: 2119.61 | R13: 2119.61 | T13: 629555050151992119,61 | U13: #N/A | V13: Atrasado | W13: 0 | X13: =IF(Faturamento!$V152="Pago",IFERROR(W13-R13,0),0) -> -2119.61 | Z13: Cobrança Regular
A14: =VLOOKUP(B14,base!A:M,11,FALSE) -> TRIFÁSICO | B14: 10/364440-8 | C14: 67991120875 | D14: 62955505015199 | E14: energisa_ms | F14: Igreja do Evangelho Quadrangular | G14: 45717 | H14: =Faturamento!$B239&Faturamento!$G239 -> 10/40190-145658 | I14: SIM | J14: 2706 | K14: 3024.93 | L14: 2323.2125 | M14: =IF(Faturamento!$S239<>"","Não emitido",IF(Faturamento!$I239="NÃO","Pendente Fatura", IF(Faturamento!$R239<>"","Aprovado",IF(Faturamento!$O239<>0,"Pendente Emissão","Processo de Calculo")))) -> Aprovado | N14: 2806.87 | O14: 2105.15 | R14: 2105.15 | T14: 629555050151992105,15 | V14: Pago | W14: 2105.15 | X14: =IF(Faturamento!$V824="Pago",IFERROR(W14-R14,0),0) -> 0
A15: =VLOOKUP(B15,base!A:M,11,FALSE) -> TRIFÁSICO | B15: 10/364440-8 | C15: 67991120875 | D15: 62955505015199 | E15: energisa_ms | F15: Igreja do Evangelho Quadrangular | G15: 45689 | H15: =Faturamento!$B170&Faturamento!$G170 -> 10/1081489-545839 | I15: SIM | J15: 2675 | K15: 2986.01 | L15: 2292.3025 | M15: =IF(Faturamento!$S170<>"","Não emitido",IF(Faturamento!$I170="NÃO","Pendente Fatura", IF(Faturamento!$R170<>"","Aprovado",IF(Faturamento!$O170<>0,"Pendente Emissão","Processo de Calculo")))) -> Aprovado | N15: 2774.83 | O15: 2081.12 | R15: 2081.12 | T15: 629555050151992081,12 | V15: Pago | W15: 2081.12 | X15: =IF(Faturamento!$V823="Pago",IFERROR(W15-R15,0),0) -> 0
A16: =VLOOKUP(B16,base!A:M,11,FALSE) -> TRIFÁSICO | B16: 10/364440-8 | C16: 67991120875 | D16: 62955505015199 | E16: energisa_ms | F16: Igreja do Evangelho Quadrangular | G16: 45658 | H16: =Faturamento!$B74&Faturamento!$G74 -> 10/925970-645717 | I16: SIM | J16: 2468 | K16: 2959.61 | L16: 2270.875 | M16: =IF(Faturamento!$S74<>"","Não emitido",IF(Faturamento!$I74="NÃO","Pendente Fatura", IF(Faturamento!$R74<>"","Aprovado",IF(Faturamento!$O74<>0,"Pendente Emissão","Processo de Calculo")))) -> Aprovado | N16: 2754.94 | O16: 2066.21 | R16: 2066.21 | T16: 629555050151992066,21 | V16: Pago | W16: 2066.21 | X16: =IF(Faturamento!$V822="Pago",IFERROR(W16-R16,0),0) -> 0
A17: =VLOOKUP(B17,base!A:M,11,FALSE) -> TRIFÁSICO | B17: 10/364440-8 | C17: 67991120875 | D17: 62955505015199 | E17: energisa_ms | F17: Igreja do Evangelho Quadrangular | G17: 45778 | H17: =Faturamento!$B433&Faturamento!$G433 -> 10/1035655-845778 | I17: SIM | J17: 2659 | K17: 2986.81 | L17: 2298.085 | M17: =IF(Faturamento!$S433<>"","Não emitido",IF(Faturamento!$I433="NÃO","Pendente Fatura", IF(Faturamento!$R433<>"","Aprovado",IF(Faturamento!$O433<>0,"Pendente Emissão","Processo de Calculo")))) -> Aprovado | N17: 2754.9 | O17: 2066.18 | R17: 2066.18 | T17: 629555050151992066,18 | V17: Atrasado | W17: 0 | X17: =IF(Faturamento!$V174="Pago",IFERROR(W17-R17,0),0) -> -2066.18 | Z17: Cobrança Regular
A18: =VLOOKUP(B18,base!A:M,11,FALSE) -> TRIFÁSICO | B18: 10/5202-7 | C18: 67 996469842 | D18: 62955505016160 | E18: energisa_ms | F18: IGREJA DO EVANGELHO QUADRANGULAR | G18: 45931 | H18: =Faturamento!$B934&Faturamento!$G934 -> 10/2344751-945778 | I18: SIM | J18: 1901 | K18: 2715.2643 | L18: 2062.9085 | M18: Aprovado | N18: 2332.5143 | O18: 1680.16 | P18: 45967 | Q18: 45974 | R18: 1680.16 | T18: =D18&R18 -> 629555050161601680,16 | U18: 09/00013026927-5 | V18: Pago | W18: =R18 -> 1680.16 | X18: =IF(Faturamento!$V936="Pago",IFERROR(W18-R18,0),0) -> 0
A19: =VLOOKUP(B19,base!A:M,11,FALSE) -> TRIFÁSICO | B19: 10/5202-7 | C19: 67 996469842 | D19: 62955505393207 | E19: energisa_ms | F19: Igreja do Evangelho Quadrangular | G19: 45748 | H19: =Faturamento!$B337&Faturamento!$G337 -> 10/109074-545748 | I19: SIM | J19: 2042 | K19: 2540.49 | L19: 1993.31 | M19: =IF(Faturamento!$S337<>"","Não emitido",IF(Faturamento!$I337="NÃO","Pendente Fatura", IF(Faturamento!$R337<>"","Aprovado",IF(Faturamento!$O337<>0,"Pendente Emissão","Processo de Calculo")))) -> Aprovado | N19: 2188.72 | O19: 1641.54 | R19: 1641.54 | T19: 629555053932071641,54 | V19: Pago | W19: 1641.54 | X19: =IF(Faturamento!$V821="Pago",IFERROR(W19-R19,0),0) -> 0
A20: =VLOOKUP(B20,base!A:M,11,FALSE) -> TRIFÁSICO | B20: 10/5202-7 | C20: 67 996469842 | D20: 62955505393207 | E20: energisa_ms | F20: Igreja do Evangelho Quadrangular | G20: 45689 | H20: =Faturamento!$B177&Faturamento!$G177 -> 10/3092868-345931 | I20: SIM | J20: 1810 | K20: 2324.4 | L20: 1854.24 | M20: =IF(Faturamento!$S177<>"","Não emitido",IF(Faturamento!$I177="NÃO","Pendente Fatura", IF(Faturamento!$R177<>"","Aprovado",IF(Faturamento!$O177<>0,"Pendente Emissão","Processo de Calculo")))) -> Aprovado | N20: 1880.64 | O20: 1410.48 | R20: 1410.48 | T20: 629555053932071410,48 | V20: Pago | W20: 1410.48 | X20: =IF(Faturamento!$V820="Pago",IFERROR(W20-R20,0),0) -> 0
A21: =VLOOKUP(B21,base!A:M,11,FALSE) -> TRIFÁSICO | B21: 10/2605731-5 | C21: 67992637973 | D21: 62955505017213 | E21: energisa_ms | F21: Igreja do Evangelho Quadrangular | G21: 45658 | H21: =Faturamento!$B67&Faturamento!$G67 -> 10/202838-945901 | I21: SIM | J21: 1682 | K21: 2029.18 | L21: 1593.43 | M21: =IF(Faturamento!$S67<>"","Não emitido",IF(Faturamento!$I67="NÃO","Pendente Fatura", IF(Faturamento!$R67<>"","Aprovado",IF(Faturamento!$O67<>0,"Pendente Emissão","Processo de Calculo")))) -> Aprovado | N21: 1743 | O21: 1307.25 | R21: 1307.25 | T21: 629555050172131307,25 | V21: Pago | W21: 1307.25 | X21: =IF(Faturamento!$V819="Pago",IFERROR(W21-R21,0),0) -> 0
A22: =VLOOKUP(B22,base!A:M,11,FALSE) -> TRIFÁSICO | B22: 10/364440-8 | C22: 67991120875 | D22: 62955505015199 | E22: energisa_ms | F22: IGREJA DO EVANGELHO QUADRANGULAR | G22: 45931 | H22: =Faturamento!$B935&Faturamento!$G935 -> 10/31292-645778 | I22: SIM | J22: 1399 | K22: 3275.3774 | L22: 2794.8836 | M22: Aprovado | N22: 1718.0174 | O22: 1237.52 | P22: 45967 | Q22: 45974 | R22: 1237.52 | T22: =D22&R22 -> 629555050151991237,52 | U22: 09/00013026929-1 | V22: Pago | W22: =R22 -> 1237.52 | X22: =IF(Faturamento!$V937="Pago",IFERROR(W22-R22,0),0) -> 0
A23: =VLOOKUP(B23,base!A:M,11,FALSE) -> TRIFÁSICO | B23: 10/5202-7 | C23: 67 996469842 | D23: 62955505393207 | E23: energisa_ms | F23: Igreja do Evangelho Quadrangular | G23: 45778 | H23: =Faturamento!$B434&Faturamento!$G434 -> 10/162736-345748 | I23: SIM | J23: 1458 | K23: 2221.7649 | L23: 1810.2987 | M23: =IF(Faturamento!$S434<>"","Não emitido",IF(Faturamento!$I434="NÃO","Pendente Fatura", IF(Faturamento!$R434<>"","Aprovado",IF(Faturamento!$O434<>0,"Pendente Emissão","Processo de Calculo")))) -> Aprovado | N23: 1645.8649 | O23: 1234.4 | R23: 1234.4 | T23: 629555053932071234,4 | V23: Pago | W23: 1234.4 | X23: =IF(Faturamento!$V818="Pago",IFERROR(W23-R23,0),0) -> 0
A24: =VLOOKUP(B24,base!A:M,11,FALSE) -> TRIFÁSICO | B24: 10/2605731-5 | C24: 67992637973 | D24: 62955505017213 | E24: energisa_ms | F24: Igreja do Evangelho Quadrangular | G24: 45689 | H24: =Faturamento!$B164&Faturamento!$G164 -> 10/399338-345778 | I24: SIM | J24: 1500 | K24: 1894.11 | L24: 1506.335 | M24: =IF(Faturamento!$S164<>"","Não emitido",IF(Faturamento!$I164="NÃO","Pendente Fatura", IF(Faturamento!$R164<>"","Aprovado",IF(Faturamento!$O164<>0,"Pendente Emissão","Processo de Calculo")))) -> Aprovado | N24: 1551.1 | O24: 1163.33 | R24: 1163.33 | T24: 629555050172131163,33 | V24: Pago | W24: 1163.33 | X24: =IF(Faturamento!$V817="Pago",IFERROR(W24-R24,0),0) -> 0
A25: =VLOOKUP(B25,base!A:M,11,FALSE) -> TRIFÁSICO | B25: 10/2599101-9 | C25: 67991120875 | D25: 62955505379395 | E25: energisa_ms | F25: Igreja do Evangelho Quadrangular | G25: 45717 | H25: =Faturamento!$B276&Faturamento!$G276 -> 10/76927-345658 | I25: SIM | J25: 1430 | K25: 1598.22 | L25: 1231.5075 | M25: =IF(Faturamento!$S276<>"","Não emitido",IF(Faturamento!$I276="NÃO","Pendente Fatura", IF(Faturamento!$R276<>"","Aprovado",IF(Faturamento!$O276<>0,"Pendente Emissão","Processo de Calculo")))) -> Aprovado | N25: 1466.85 | O25: 1100.14 | R25: 1100.14 | T25: 629555053793951100,14 | V25: Pago | W25: 1100.14 | X25: =IF(Faturamento!$V816="Pago",IFERROR(W25-R25,0),0) -> 0
A26: =VLOOKUP(B26,base!A:M,11,FALSE) -> TRIFÁSICO | B26: 10/2605731-5 | C26: 67992637973 | D26: 62955505017213 | E26: energisa_ms | F26: IGREJA DO EVANGELHO QUADRANGULAR | G26: 45931 | H26: =Faturamento!$B938&Faturamento!$G938 -> 10/113971-645809 | I26: SIM | J26: 1216 | K26: 1692.8924 | L26: 1284.0986 | M26: Aprovado | N26: 1461.6524 | O26: 1052.86 | P26: 45967 | Q26: 45974 | R26: 1052.86 | T26: =D26&R26 -> 629555050172131052,86 | U26: 09/00013026934-1 | V26: Pago | W26: =R26 -> 1052.86 | X26: =IF(Faturamento!$V940="Pago",IFERROR(W26-R26,0),0) -> 0
A27: =VLOOKUP(B27,base!A:M,11,FALSE) -> TRIFÁSICO | B27: 10/2599101-9 | C27: 67991120875 | D27: 62955505379395 | E27: energisa_ms | F27: IGREJA DO EVANGELHO QUADRANGULAR | G27: 45931 | H27: =Faturamento!$B940&Faturamento!$G940 -> 10/1433087-245809 | I27: SIM | J27: 1171 | K27: 1568.9311 | L27: 1165.3788 | M27: Aprovado | N27: 1442.9111 | O27: 1039.36 | P27: 45967 | Q27: 45974 | R27: 1039.36 | T27: =D27&R27 -> 629555053793951039,36 | U27: 09/00013026937-4 | V27: Pago | W27: =R27 -> 1039.36 | X27: =IF(Faturamento!$V942="Pago",IFERROR(W27-R27,0),0) -> 0
A28: =VLOOKUP(B28,base!A:M,11,FALSE) -> TRIFÁSICO | B28: 10/5202-7 | C28: 67 996469842 | D28: 62955505393207 | E28: energisa_ms | F28: Igreja do Evangelho Quadrangular | G28: 45658 | H28: =Faturamento!$B81&Faturamento!$G81 -> 10/1674177-945931 | I28: SIM | J28: 1233 | K28: 2315.08 | L28: 1970.9925 | M28: =IF(Faturamento!$S81<>"","Não emitido",IF(Faturamento!$I81="NÃO","Pendente Fatura", IF(Faturamento!$R81<>"","Aprovado",IF(Faturamento!$O81<>0,"Pendente Emissão","Processo de Calculo")))) -> Aprovado | N28: 1376.35 | O28: 1032.26 | R28: 1032.26 | T28: 629555053932071032,26 | V28: Pago | W28: 1032.26 | X28: =IF(Faturamento!$V815="Pago",IFERROR(W28-R28,0),0) -> 0
A29: =VLOOKUP(B29,base!A:M,11,FALSE) -> TRIFÁSICO | B29: 10/18015-8 | C29: 67996266684 | D29: 62955505016080 | E29: energisa_ms | F29: IGREJA DO EVANGELHO QUADRANGULAR | G29: 45931 | H29: =Faturamento!$B936&Faturamento!$G936 -> 10/18015-845809 | I29: SIM | J29: 1150 | K29: 1509.535 | L29: 1121.1263 | M29: Aprovado | N29: 1388.765 | O29: 1000.36 | P29: 45967 | Q29: 45974 | R29: 1000.36 | T29: =D29&R29 -> 629555050160801000,36 | U29: 09/00013026931-7 | V29: Pago | W29: =R29 -> 1000.36 | X29: =IF(Faturamento!$V938="Pago",IFERROR(W29-R29,0),0) -> 0
A30: =VLOOKUP(B30,base!A:M,11,FALSE) -> #N/A | B30: 10/3170252-5 | C30: #N/A | D30: 62955505035629 | E30: energisa_ms | F30: Igreja do Evangelho Quadrangular | G30: 45717 | H30: =Faturamento!$B282&Faturamento!$G282 -> 10/127464-645870 | I30: SIM | J30: 1313 | M30: =IF(Faturamento!$S282<>"","Não emitido",IF(Faturamento!$I282="NÃO","Pendente Fatura", IF(Faturamento!$R282<>"","Aprovado",IF(Faturamento!$O282<>0,"Pendente Emissão","Processo de Calculo")))) -> Aprovado | N30: 1278.94 | O30: 959.21 | S30: não emitido pela EGS | T30: 62955505035629 | V30: Não faturado | W30: 0 | X30: =IF(Faturamento!$V111="Pago",IFERROR(W30-R30,0),0) -> 0
A31: =VLOOKUP(B31,base!A:M,11,FALSE) -> TRIFÁSICO | B31: 10/18015-8 | C31: 67996266684 | D31: 62955505016080 | E31: energisa_ms | F31: Igreja do Evangelho Quadrangular | G31: 45658 | H31: =Faturamento!$B58&Faturamento!$G58 -> 10/2605731-545870 | I31: SIM | J31: 1161 | K31: 1414.3 | L31: 1100.9575 | M31: =IF(Faturamento!$S58<>"","Não emitido",IF(Faturamento!$I58="NÃO","Pendente Fatura", IF(Faturamento!$R58<>"","Aprovado",IF(Faturamento!$O58<>0,"Pendente Emissão","Processo de Calculo")))) -> Aprovado | N31: 1253.37 | O31: 940.03 | R31: 940.03 | T31: 62955505016080940,03 | V31: Pago | W31: 940.03 | X31: =IF(Faturamento!$V814="Pago",IFERROR(W31-R31,0),0) -> 0 | AA31: 283032 | AB31: 502 | AC31: Igreja do Evangelho Quadrangular | AD31: '62955505239119' | AE31: 64.91 | AG31: A Unidade Consumidora 10/341308-5 economizou R$21,64 na fatura referente à jun/2025 consumindo 86 kWh em créditos de energia renovável conforme fatura de energia. A economia foi de 25% em relação ao que seria pago para a Energisa considerando os créditos consumidos. Atenção: Mantenha as contas da Energisa em dia para evitar cortes. | AH31: monicadossantosfonseca@hotmail.com
A32: =VLOOKUP(B32,base!A:M,11,FALSE) -> TRIFÁSICO | B32: 10/2605731-5 | C32: 0 | D32: 62955505017213 | E32: energisa_ms | F32: Igreja do Evangelho Quadrangular | G32: 45901 | H32: =Faturamento!$B807&Faturamento!$G807 -> 10/3005226-045627 | I32: SIM | J32: 1005 | K32: 1446.0075 | L32: 1119.9073 | M32: Aprovado | N32: 1214.1675 | O32: 888.07 | P32: 45933 | Q32: 45943 | R32: =O32 -> 888.07 | T32: 62955505017213888,07 | U32: 09/00012851400-5 | V32: Pago | W32: =R32 -> 888.07 | X32: =IF(Faturamento!$V813="Pago",IFERROR(W32-R32,0),0) -> 0
A33: =VLOOKUP(B33,base!A:M,11,FALSE) -> TRIFÁSICO | B33: 10/18015-8 | C33: 0 | D33: 62955505016080 | E33: energisa_ms | F33: Igreja do Evangelho Quadrangular | G33: 45901 | H33: =Faturamento!$B805&Faturamento!$G805 -> 10/276283-945627 | I33: SIM | J33: 992 | K33: 1319.3932 | L33: 997.48403 | M33: Aprovado | N33: 1198.5632 | O33: 876.65 | P33: 45933 | Q33: 45943 | R33: =O33 -> 876.65 | T33: 62955505016080876,65 | U33: 09/00012851398-1 | V33: Pago | W33: =R33 -> 876.65 | X33: =IF(Faturamento!$V812="Pago",IFERROR(W33-R33,0),0) -> 0
A34: =VLOOKUP(B34,base!A:M,11,FALSE) -> TRIFÁSICO | B34: 10/202838-9 | C34: 67992637973 | D34: 62955505016403 | E34: energisa_ms | F34: Igreja do Evangelho Quadrangular | G34: 45717 | H34: =Faturamento!$B277&Faturamento!$G277 -> 10/13786-945931 | I34: SIM | J34: 1120 | K34: 1458.59 | L34: 1170.5725 | M34: =IF(Faturamento!$S277<>"","Não emitido",IF(Faturamento!$I277="NÃO","Pendente Fatura", IF(Faturamento!$R277<>"","Aprovado",IF(Faturamento!$O277<>0,"Pendente Emissão","Processo de Calculo")))) -> Aprovado | N34: 1152.07 | O34: 864.05 | R34: 864.05 | T34: 62955505016403864,05 | V34: Pago | W34: 864.05 | X34: =IF(Faturamento!$V811="Pago",IFERROR(W34-R34,0),0) -> 0
A35: =VLOOKUP(B35,base!A:M,11,FALSE) -> #N/A | B35: 10/3170252-5 | C35: #N/A | D35: 62955505035629 | E35: energisa_ms | F35: Igreja do Evangelho Quadrangular | G35: 45658 | H35: =Faturamento!$B141&Faturamento!$G141 -> 10/202838-945839 | I35: SIM | J35: 1119 | K35: 1431.63 | L35: 1152.2675 | M35: =IF(Faturamento!$S141<>"","Não emitido",IF(Faturamento!$I141="NÃO","Pendente Fatura", IF(Faturamento!$R141<>"","Aprovado",IF(Faturamento!$O141<>0,"Pendente Emissão","Processo de Calculo")))) -> Aprovado | N35: 1117.45 | O35: 838.09 | R35: 838.09 | S35: Cobrança indevida (Planilha Rubia) | T35: 62955505035629838,09 | V35: Cancelado | W35: 0 | X35: =IF(Faturamento!$V61="Pago",IFERROR(W35-R35,0),0) -> -838.09
A36: =VLOOKUP(B36,base!A:M,11,FALSE) -> TRIFÁSICO | B36: 10/2599101-9 | C36: 0 | D36: 62955505379395 | E36: energisa_ms | F36: Igreja do Evangelho Quadrangular | G36: 45901 | H36: =Faturamento!$B809&Faturamento!$G809 -> 10/3092868-345627 | I36: SIM | J36: 909 | K36: 1221.2946 | L36: 926.3692 | M36: Aprovado | N36: 1098.0946 | O36: 803.17 | P36: 45933 | Q36: 45943 | R36: =O36 -> 803.17 | T36: 62955505379395803,17 | U36: 09/00012851402-1 | V36: Pago | W36: =R36 -> 803.17 | X36: =IF(Faturamento!$V810="Pago",IFERROR(W36-R36,0),0) -> 0
A37: =VLOOKUP(B37,base!A:M,11,FALSE) -> #N/A | B37: 10/2247256-7 | C37: #N/A | D37: 62955505015199 | E37: energisa_ms | F37: Igreja do Evangelho Quadrangular | G37: 45689 | H37: =Faturamento!$B186&Faturamento!$G186 -> 10/8777-545778 | I37: SIM | J37: 936 | K37: 1270.54 | L37: 1024.3025 | M37: =IF(Faturamento!$S186<>"","Não emitido",IF(Faturamento!$I186="NÃO","Pendente Fatura", IF(Faturamento!$R186<>"","Aprovado",IF(Faturamento!$O186<>0,"Pendente Emissão","Processo de Calculo")))) -> Aprovado | N37: 984.95 | O37: 738.71 | R37: 738.71 | T37: 62955505015199738,71 | V37: Atrasado | W37: 0 | X37: =IF(Faturamento!$V66="Pago",IFERROR(W37-R37,0),0) -> -738.71 | Z37: Cobrança Regular | AI37: =VLOOKUP(B37,'[2]Conciliação - 022025'!$A:$L,12,FALSE) -> VALOR DEVIDO - Cancelamento via email dia 23/04, tenho tudo formalizado por whatsapp com Danilo Silva
A38: =VLOOKUP(B38,base!A:M,11,FALSE) -> TRIFÁSICO | B38: 10/202838-9 | C38: 67992637973 | D38: 62955505016403 | E38: energisa_ms | F38: Igreja do Evangelho Quadrangular | G38: 45689 | H38: =Faturamento!$B158&Faturamento!$G158 -> 10/3139326-745931 | I38: SIM | J38: 957 | K38: 1253.95 | L38: 1008.1475 | M38: =IF(Faturamento!$S158<>"","Não emitido",IF(Faturamento!$I158="NÃO","Pendente Fatura", IF(Faturamento!$R158<>"","Aprovado",IF(Faturamento!$O158<>0,"Pendente Emissão","Processo de Calculo")))) -> Aprovado | N38: 983.21 | O38: 737.41 | R38: 737.41 | T38: 62955505016403737,41 | V38: Pago | W38: 737.41 | X38: =IF(Faturamento!$V809="Pago",IFERROR(W38-R38,0),0) -> 0
A39: =VLOOKUP(B39,base!A:M,11,FALSE) -> TRIFÁSICO | B39: 10/18015-8 | C39: 67996266684 | D39: 62955505016080 | E39: energisa_ms | F39: Igreja do Evangelho Quadrangular | G39: 45689 | H39: =Faturamento!$B155&Faturamento!$G155 -> 10/72605-945931 | I39: SIM | J39: 875 | K39: 1044.82 | L39: 809.205 | M39: =IF(Faturamento!$S155<>"","Não emitido",IF(Faturamento!$I155="NÃO","Pendente Fatura", IF(Faturamento!$R155<>"","Aprovado",IF(Faturamento!$O155<>0,"Pendente Emissão","Processo de Calculo")))) -> Aprovado | N39: 942.46 | O39: 706.85 | R39: 706.85 | T39: 62955505016080706,85 | V39: Pago | W39: 706.85 | X39: =IF(Faturamento!$V808="Pago",IFERROR(W39-R39,0),0) -> 0
A40: =VLOOKUP(B40,base!A:M,11,FALSE) -> TRIFÁSICO | B40: 10/2599101-9 | C40: 67991120875 | D40: 62955505379395 | E40: energisa_ms | F40: Igreja do Evangelho Quadrangular | G40: 45748 | H40: =Faturamento!$B373&Faturamento!$G373 -> 10/1130988-745901 | I40: SIM | J40: 897 | K40: 1038.33 | L40: 803.3325 | M40: =IF(Faturamento!$S373<>"","Não emitido",IF(Faturamento!$I373="NÃO","Pendente Fatura", IF(Faturamento!$R373<>"","Aprovado",IF(Faturamento!$O373<>0,"Pendente Emissão","Processo de Calculo")))) -> Aprovado | N40: 939.99 | O40: 704.99 | R40: 704.99 | T40: 62955505379395704,99 | V40: Pago | W40: 704.99 | X40: =IF(Faturamento!$V807="Pago",IFERROR(W40-R40,0),0) -> 0
...

Sheet Acordos
A1: Instalação | B1: Valor total | C1: Referência Negociadas | D1: Data de Pagamento | E1: Forma de Pagamento | F1: Status | G1: Verificação extrato | H1: Responsável Verificação
A2: 10/175073-6 | B2: 117.9 | C2: Jan/25, Fev/25, Mar/25, Abr/25 e Mai/25 | D2: 45888 | E2: Pix | F2: Quitado | G2: ok | H2: Carol
A3: 10/987178-1 | B3: 10.88 | C3: 45748 | D3: 45895 | E3: Pix | F3: Quitado | G3: ok | H3: Carol
A4: 10/3123706-8 | B4: 266.72 | C4: Abr/25 e Maio/25 | D4: 45897 | E4: Pix | F4: Quitado | G4: ok | H4: Carol
A5: 10/113971-6 | B5: 86.94 | C5: 45839 | D5: 45897 | E5: Pix | F5: Quitado | G5: ok | H5: Carol
A6: 10/530195-7 | B6: 239.06 | C6: Jan/25, Abr/25, Mai/25 e Jun/25 | D6: 1ª Parc. Dia 04/09 - Pago (Valor R$ 119,53) 2ª Parc. Dia 25/09 - Pago (Valor R$ 119,53) | E6: Pix | F6: Quitado | G6: ok | H6: Carol
A7: 10/341308-5 | B7: 203.23 | C7: 45778 | D7: 45901 | E7: Pix | F7: Quitado | G7: ok | H7: Carol
A8: 10/1117293-9 | B8: 293.26 | C8: Jan/25, Abr/25, Mai/25, Jun/25 e Jul/25 | D8: 45901 | E8: Pix | F8: Quitado | G8: ok | H8: Carol
A9: 10/3125732-2 | B9: 104.66 | C9: 45839 | D9: 45901 | E9: Pix | F9: Quitado | G9: ok | H9: Carol
A10: 10/78338-1 | B10: 176.78 | C10: 45778 | D10: 45901 | E10: Pix | F10: Quitado | G10: ok | H10: Carol
A11: 10/3139326-7 | B11: 321.21 | C11: 45839 | D11: 45901 | E11: Pix | F11: Quitado | G11: ok | H11: Carol
A12: 10/142353-2 | B12: 282.64 | C12: 45839 | D12: 45901 | E12: Pix | F12: Quitado | G12: ok | H12: Carol
A13: 10/76927-3 | B13: 71.45 | C13: 45839 | D13: 45904 | E13: Pix | F13: Quitado | G13: ok | H13: Carol
A14: 10/175073-6 | B14: 149.22 | C14: Pagamento em Duplicidade (Fev/25 à Maio/25 - Sem desconto) | D14: 45904 | E14: Pix | F14: Quitado | G14: ok | H14: Carol
A15: 10/3123706-8 | B15: 238.05 | C15: 45839 | D15: 45904 | E15: Pix | F15: Quitado | G15: ok | H15: Carol
A16: 10/41548-9 | B16: 592.39 | C16: Abr/25, Maio/25, Junho/25 e Julho/25 | D16: 1ª Parc. Dia 10/09 - Pago (Valor R$ 202,39) 2ª Parc. Dia 21/10 - Pago (Valor R$ 195,00) 3ª Parc. Dia 12/11 - Pago (Valor R$ 195,00) | E16: Pix | F16: Quitado | G16: ok | H16: Carol
A17: 10/1184751-4 | B17: 147.52 | C17: Jul/25 pago em duplicidade | D17: 45904 | E17: Pix | F17: Quitado | G17: ok | H17: Carol
A18: 10/1288241-1 | B18: 387.03 | C18: Abr/25, Maio/25, Jun/25 e Jul/25 | D18: 1ª Parc. Dia 18/09 - Pago (Valor R$ 129,01) 2ª Parc. Dia 09/10 - Pago (Valor R$ 129,01) 3ª Parc. Dia 07/11 - Pago (Valor R$ 129,01) | E18: Pix | F18: Quitado | G18: ok | H18: Carol
A19: 10/2794432-1 | B19: 87.86 | C19: 45778 | D19: 45917 | E19: Pix | G19: ok | H19: Carol
A20: 10/63920-3 | B20: 200.59 | C20: 45778 | D20: 45917 | E20: Pix | F20: Quitado | G20: ok | H20: Carol
A21: 10/384823-1 | B21: 250.43 | C21: Abr/25 e Maio/25 | D21: 45917 | E21: Pix | F21: Quitado | G21: ok | H21: Carol
A22: 10/52987-5 | B22: 45.6 | C22: 45809 | D22: 45918 | E22: Pix | F22: Quitado | G22: ok | H22: Carol
A23: 10/69319-2 | B23: 278.35 | C23: Abril/25 e Junho/25 | D23: 45918 | E23: Pix | F23: Quitado | G23: ok | H23: Carol
A24: 10/1184751-4 | B24: 221.18 | C24: 45778 | D24: 45922 | E24: Pix | F24: Quitado | G24: ok | H24: Carol
A25: 10/61344-8 | B25: 356.23 | C25: 45839 | D25: 45925 | E25: Pix | F25: Quitado | G25: ok | H25: Carol
A26: 10/952579-1 | B26: 124.38 | C26: 45778 | D26: 45925 | E26: Pix | F26: Quitado | G26: ok | H26: Carol
A27: 10/260761-2 | B27: 355.03 | C27: 45778 | D27: 45925 | E27: Pix | F27: Quitado | G27: ok | H27: Carol
A28: 10/226667-4 | B28: 30.62 | C28: 45778 | D28: 45926 | E28: Pix | F28: Quitado | G28: ok | H28: Carol
A29: 10/452884-0 | B29: 98.642704 | C29: Maio/25 pago em duplicidade | D29: 45926 | E29: Pix | F29: Quitado | G29: ok | H29: Carol
A30: 10/8777-5 | B30: 355.68 | C30: 45778 | D30: 45926 | E30: Pix | F30: Quitado | G30: ok | H30: Carol
A31: 10/1081489-5 | B31: 351.64 | C31: 45748 | D31: 45929 | E31: Pix | F31: Quitado | G31: ok | H31: Carol
A32: 10/1081489-5 | B32: 236.57816 | C32: 45809 | D32: 45929 | E32: Pix | F32: Quitado | G32: ok | H32: Carol
A33: 10/395471-6 | B33: 541.04 | C33: Jan/25, Abr/25 e Maio/25 | D33: 45929 | E33: Pix | F33: Quitado | G33: ok | H33: Carol
A34: 10/129490-9 | B34: 200.22 | C34: 45748 | D34: 45930 | E34: Pix | F34: Quitado | G34: ok | H34: Carol
A35: 10/532723-4 | B35: 318.63 | C35: 45748 | D35: 45930 | E35: Pix | F35: Quitado | G35: ok | H35: Carol
A36: 10/129490-9 | B36: 203.2525 | C36: 45839 | D36: 45931 | E36: Pix | F36: Quitado | G36: ok | H36: Carol
A37: 10/276283-9 | B37: 148.43 | C37: 45809 | D37: 45937 | E37: Pix | F37: Quitado | G37: ok | H37: Carol
A38: 10/532081-7 | B38: 311.42 | C38: 45658 | D38: 45938 | E38: Pix | F38: Quitado | G38: ok | H38: Carol
A39: 10/532081-7 | B39: 176.55 | C39: 45748 | D39: 45938 | E39: Pix | F39: Quitado | G39: ok | H39: Carol
A40: 10/156956-5 | B40: 202.72 | C40: 45778 | D40: 45937 | E40: Pix | F40: Quitado | G40: ok | H40: Carol
...

Sheet Negociações
A1: INSTALAÇÃO | B1: REFERÊNCIA | C1: VALOR POR REFERÊNCIA | D1: VALOR PAGO | E1: FORMA DE PAGAMENTO | F1: VENCIMENTO PARCELAS | G1: DATA DE PAGAMENTO | H1: STATUS
A2: 10/530195-7 | B2: 45658 | C2: 41.5 | D2: 41.5 | E2: Pix | F2: 45904 | G2: 45904 | H2: Pago
A3: 10/530195-7 | B3: 45748 | C3: 48.78 | D3: 48.78 | E3: Pix
A4: 10/530195-7 | B4: 45778 | C4: 61.11 | D4: 61.11 | E4: Pix | F4: 25/09/2025 | G4: 25/09/2025 | H4: Pago
A5: 10/530195-7 | B5: 45809 | C5: 87.67 | D5: 87.67 | E5: Pix
A6: 10/41548-9 | B6: 45748 | C6: 233.78 | D6: 233.78 | E6: Pix | F6: 45910 | G6: 45910 | H6: Pago
A7: 10/41548-9 | B7: 45778 | C7: 199.219 | D7: 199.219 | E7: Pix | F7: 45951 | G7: 21/10/2025 | H7: Pago
A8: 10/41548-9 | B8: 45809 | C8: 157.39333 | D8: 157.39333 | E8: Pix | F8: 45973 | G8: 45973 | H8: Pago
A9: 10/41548-9 | B9: 45839 | C9: 2 | D9: 2 | E9: Pix
A10: 10/1288241-1 | B10: 45748 | C10: 387.03 | D10: 387.03 | E10: Pix | F10: 45918 | G10: 45918 | H10: Pago
A11: 10/1288241-1 | F11: 45940 | G11: 45939 | H11: Pago
A12: 10/1288241-1 | F12: 45971 | G12: 45968 | H12: Pago
A13: 10/341308-5 | B13: 45748 | C13: 233.62 | D13: 233.62 | E13: Pix | F13: 45943 | G13: 1ª Parc. Dia 13/10/2025 - Pago (Valor R$ 300,00) | H13: Pago
